Workbook

Sheet Cover
B3: MAJOR EUROPEAN G-SIB — ALM MASTER MODEL
B4: Asset-Liability Management | Full-Cycle ALM Engine
B5: Calibrated to Q4 2025 Actuals | Basel III / CRR2 / EBA/GL/2022/14
B7: MODEL OVERVIEW
B8: Institution | C8: =Engine!C108 -> Major European G-SIB
B9: Reporting Currency | C9: =Engine!C106&" — "&Engine!C107 -> EUR — EUR millions
B10: Base Year | C10: =Engine!C105 -> 2025A
B11: Forecast Horizon | C11: =Engine!C110 -> 3 Years (2026F–2028F)
B12: Regulatory Framework | C12: =Engine!C109 -> EU — Basel III / CRR2 / Del. Reg. (EU) 2022/786
B13: Scenarios | C13: Base | Rate Hike | Rate Cut | Stress
B14: Model Version | C14: =Engine!C103 -> v10
B16: ARCHITECTURE
B17: Sheet | C17: Role
B18: Dashboard | C18: Executive ALCO view — scenario selector, KPI cards, NII waterfall, EVE sensitivity
B19: Engine | C19: Central control layer — rate curve, scenario inputs, CHOOSE-based propagation
B20: Model | C20: Full analytical engine — 18 modular sections, 1,000+ formulas
B21: Master Balance Sheet | C21: Source-of-truth balance sheet — actuals + three forecast years
B22: KEY METRICS SNAPSHOT (Base Scenario — 2026F)
B23: NII (€bn) | C23: NIM | D23: CET1 | E23: LCR | F23: NSFR | G23: EVE/Tier 1
B24: =Dashboard!B8 -> 22.685669 | C24: =Dashboard!C8 -> 0.017379544 | D24: =Dashboard!D8 -> 0.15879656 | E24: =Dashboard!E8 -> 1.5354828 | F24: =Dashboard!F8 -> 0.9602036 | G24: =Dashboard!G8 -> 0.1324464
B26: AUTHOR
B27: Name | C27: =Engine!F111 -> Hossam Eltarrass
B28: Role | C28: ALM Intern | BSc Banking & Finance — University of Siena
B29: LinkedIn | C29: linkedin.com/in/hossameltarrass
B30: GitHub | C30: github.com/hossam-eltarrass
B31: Last Updated | C31: 46157
B33: DATA SOURCE & DISCLAIMER
B34: Balance sheet actuals calibrated to Q4 2025 public disclosures of a major European G-SIB (publicly available Pillar 3 report). No proprietary data used.
B35: Model built to bank-level standard for portfolio purposes. All regulatory references are to publicly available EBA guidelines and EU regulations.
B37: ="Model "&Engine!C103&" | Last updated: "&TEXT(Engine!C111,"DD-MMM-YYYY")&" | Prepared by: "&Engine!F111 -> Model v10 | Last updated: 15-May-2026 | Prepared by: Hossam Eltarrass

Sheet Dashboard
B2: MAJOR EUROPEAN G-SIB — ALM MASTER MODEL | G2: ▸ ACTIVE SCENARIO
B3: =Engine!C108&" | "&Engine!C106&" | Scenario: "&CHOOSE(Engine!C4,"Base","Rate Hike","Rate Cut","Stress")&" | Base year: "&Engine!C105 -> Major European G-SIB | EUR | Scenario: Base | Base year: 2025A | G3: Base
B4: Forecast: 2026F–2028F | Basel III / CRR2 / Del. Reg. (EU) 2022/786 / EBA/GL/2022/14 | G4: =MATCH(G3,{"Base","Rate Hike","Rate Cut","Stress"},0) -> 1
B6: ="KEY METRICS — 2026F vs 2025A | "&CHOOSE(Dashboard!G4,"Base","Rate Hike","Rate Cut","Stress") -> KEY METRICS — 2026F vs 2025A | Base
B7: NII (€bn) | C7: NIM | D7: CET1 Ratio | E7: LCR | F7: NSFR | G7: EVE / Tier 1
B8: =Model!D23/1000 -> 22.685669 | C8: =Model!E137 -> 0.017379544 | D8: =Model!E143 -> 0.15879656 | E8: =Model!E145 -> 1.5354828 | F8: =Model!E146 -> 0.9602036 | G8: =Model!E225 -> 0.1324464
B9: =(Model!D23-Model!C23)/1000 -> 0.6004161 | C9: =Model!E137-Model!D137 -> 6.0649992e-05 | D9: =Model!E143-Model!D143 -> 0.0013406131 | E9: =Model!E145-Model!D145 -> -0.018924085 | F9: =Model!E146-Model!D146 -> -0.059624667 | G9: =IF(Model!E225>0.15,"BREACH","OK") -> OK
D10: min 13.5% | E10: min 100% | F10: min 1.00x | G10: outlier >15%
B12: BALANCE SHEET FORECAST (EUR millions)
C13: 2025A | D13: 2026F | E13: 2027F | F13: 2028F
B14: ASSETS
B15: Cash & CB reserves | C15: =Engine!D126 -> 211330 | D15: =Engine!E126 -> 214325.33 | E15: =Engine!F126 -> 217157.6 | F15: =Engine!G126 -> 219876.42
B16: Trading assets | C16: =Engine!D127 -> 870245 | D16: =Engine!E127 -> 870245 | E16: =Engine!F127 -> 870245 | F16: =Engine!G127 -> 870245
B17: Loans to customers | C17: =Engine!D128 -> 897358 | D17: =Engine!E128 -> 924278.74 | E17: =Engine!F128 -> 952007.1 | F17: =Engine!G128 -> 980567.32
B18: Interbank loans | C18: =Engine!D129 -> 26259 | D18: =Engine!E129 -> 26259 | E18: =Engine!F129 -> 26259 | F18: =Engine!G129 -> 26259
B19: Securities | C19: =Engine!D130 -> 153107 | D19: =Engine!E130 -> 157700.21 | E19: =Engine!F130 -> 162431.22 | F19: =Engine!G130 -> 167304.15
B20: Other assets | C20: =Engine!D131 -> 634682 | D20: =Engine!E131 -> 641028.82 | E20: =Engine!F131 -> 647439.11 | F20: =Engine!G131 -> 653913.5
B21: TOTAL ASSETS | C21: =Engine!D132 -> 2792981 | D21: =Engine!E132 -> 2833837.1 | E21: =Engine!F132 -> 2875539 | F21: =Engine!G132 -> 2918165.4
B23: LIABILITIES & EQUITY
B24: Customer deposits | C24: =Engine!D136 -> 1075564 | D24: =Engine!E136 -> 1102453.1 | E24: =Engine!F136 -> 1130014.4 | F24: =Engine!G136 -> 1158264.8
B25: Interbank funding | C25: =Engine!D137 -> 69938 | D25: =Engine!E137 -> 69938 | E25: =Engine!F137 -> 69938 | F25: =Engine!G137 -> 69938
B26: Repo funding | C26: =Engine!D138 -> 357947 | D26: =Engine!E138 -> 357947 | E26: =Engine!F138 -> 357947 | F26: =Engine!G138 -> 357947
B27: Bonds issued | C27: =Engine!D139 -> 173933 | D27: =Engine!E139 -> 173933 | E27: =Engine!F139 -> 173933 | F27: =Engine!G139 -> 173933
B28: Subordinated debt | C28: =Engine!D140 -> 34468 | D28: =Engine!E140 -> 34468 | E28: =Engine!F140 -> 34468 | F28: =Engine!G140 -> 34468
B29: Other liabilities | C29: =Engine!D141 -> 948958 | D29: =Engine!E141 -> 958447.58 | E29: =Engine!F141 -> 968032.06 | F29: =Engine!G141 -> 977712.38
B30: TOTAL LIABILITIES | C30: =Engine!D142 -> 2660808 | D30: =Engine!E142 -> 2697186.7 | E30: =Engine!F142 -> 2734332.5 | F30: =Engine!G142 -> 2772263.2
B31: Equity | C31: =Engine!D145 -> 132173 | D31: =Engine!E145 -> 136650.42 | E31: =Engine!F145 -> 141206.54 | F31: =Engine!G145 -> 145902.22
B32: TOTAL LIABILITIES + EQUITY | C32: =Engine!D146 -> 2792981 | D32: =Engine!E146 -> 2833837.1 | E32: =Engine!F146 -> 2875539 | F32: =Engine!G146 -> 2918165.4
B33: Balance sheet check | C33: =Engine!D147 -> 0 | D33: =Engine!E147 -> 0 | E33: =Engine!F147 -> 0 | F33: =Engine!G147 -> 0
B35: PROFITABILITY (EUR millions)
C36: 2025A | D36: 2026F | E36: 2027F | F36: 2028F
B37: ="Model "&Engine!C103&" | Last updated: "&TEXT(Engine!C111,"DD-MMM-YYYY")&" | Prepared by: "&Engine!F111 -> Model v10 | Last updated: 15-May-2026 | Prepared by: Hossam Eltarrass | C37: =Model!C23 -> 22085.252 | D37: =Model!D23 -> 22685.669 | E37: =Model!E23 -> 23224.923 | F37: =Model!F23 -> 24295.945
B38: Fee income | C38: =Model!C24 -> 22343.848 | D38: =Model!D24 -> 22670.697 | E38: =Model!E24 -> 23004.312 | F38: =Model!F24 -> 23345.323
B39: Total Revenue | C39: =Model!C25 -> 44429.1 | D39: =Model!D25 -> 45356.365 | E39: =Model!E25 -> 46229.236 | F39: =Model!F25 -> 47641.269
B40: Operating Expenses | C40: =Model!C26 -> -27546.042 | D40: =Model!D26 -> -28120.946 | E40: =Model!E26 -> -28662.126 | F40: =Model!F26 -> -29537.586
B41: Provisions / CoR | C41: =Model!C28 -> -2243.395 | D41: =Model!D28 -> -2310.6968 | E41: =Model!E28 -> -2380.0178 | F41: =Model!F28 -> -2451.4183
B42: Net Income | C42: =Model!C31 -> 10979.747 | D42: =Model!D31 -> 11193.541 | E42: =Model!E31 -> 11390.319 | F42: =Model!F31 -> 11739.198
B44: NIM | C44: =Model!D137 -> 0.017318894 | D44: =Model!E137 -> 0.017379544 | E44: =Model!F137 -> 0.017329328 | F44: =Model!G137 -> 0.017657824
B45: ROE | C45: =Model!C34 -> 0.083071031 | D45: =Model!D34 -> 0.083278024 | E45: =Model!E34 -> 0.080624402 | F45: =Model!F34 -> 0.081775265
B46: Cost-to-Income | C46: =Model!C36 -> 0.62 | D46: =Model!D36 -> 0.62 | E46: =Model!E36 -> 0.62 | F46: =Model!F36 -> 0.62
...

Sheet Master Balance Sheet
B1: MAJOR EUROPEAN G-SIB — ALM Master Model | Master Balance Sheet | EUR millions
B2: Line Item | C2: 2024A | D2: 2025A
B3: ASSETS
B4: Cash and balances at central banks | C4: 182496 | D4: 211330
B5: Financial instruments FVTPL — trading | C5: 267357 | D5: 321293
B6: Financial instruments FVTPL — non-trading | C6: 225699 | D6: 254310
B7: Financial instruments FVTPL — designated | C7: 322631 | D7: 274625
B8: Derivatives used for hedging purposes (asset) | C8: 20851 | D8: 20017
B9: Financial assets FVOCI — Equity instruments WARNING: NOT HQLA — use MBS row 10 NOT row 9 | C9: 71430 | D9: 77940
B10: Financial assets FVOCI — Debt instruments ✓ HQLA eligible | C10: 1610 | D10: 1420
B11: Financial assets amortised cost — Loans to credit institutions | C11: 31147 | D11: 26259
B12: Financial assets amortised cost — Loans to customers | C12: 900141 | D12: 897358
B13: Financial assets amortised cost — Debt securities ✓ HQLA eligible | C13: 146975 | D13: 151687
B14: Remeasurement adjustment on interest-rate risk hedges | C14: -758 | D14: -2335
B15: Insurance investment assets WARNING: 100% RSF per CRR Art.428ab | C15: 286849 | D15: 305471
... B21: Goodwill | C21: 5550 | D21: 7133
B22: Assets held for sale | D22: 7805
B23: TOTAL ASSETS | C23: 2704908 | D23: 2792981
B24: LIABILITIES
B25: Deposits from central banks | C25: 3366 | D25: 4401
B26: Financial liabilities FVTPL — trading | C26: 79958 | D26: 98487
B27: Financial liabilities FVTPL — repo / structured | C27: 304817 | D27: 357947
B28: Financial liabilities FVTPL — other trading | C28: 104934 | D28: 129279
B29: Financial liabilities FVTPL — designated | C29: 301953 | D29: 252726
B30: Derivatives used for hedging purposes (liability) WARNING: EXCLUDE from IRRBB | C30: 36864 | D30: 28493
B31: Financial liabilities AC — Deposits from credit institutions | C31: 66872 | D31: 69938
B32: Financial liabilities AC — Customer deposits | C32: 1034857 | D32: 1075564
B33: Financial liabilities AC — Debt securities issued | C33: 198119 | D33: 173933
B34: Financial liabilities AC — Subordinated debt | C34: 31799 | D34: 34468
B35: Remeasurement adjustment on interest-rate risk hedges | C35: -10696 | D35: -9811
B36: Current and deferred tax liabilities | C36: 3657 | D36: 3336
B37: ="Model "&Engine!C103&" | Last updated: "&TEXT(Engine!C111,"DD-MMM-YYYY")&" | Prepared by: "&Engine!F111 -> Model v10 | Last updated: 15-May-2026 | Prepared by: Hossam Eltarrass | C37: 136955 | D37: 143059
B38: Insurance contract liabilities | C38: 247699 | D38: 261223
B39: Financial liabilities — insurance activities | C39: 19807 | D39: 21500
B40: Provisions for contingencies and charges | C40: 9806 | D40: 10193
B41: Liabilities associated with assets held for sale | D41: 6072
B42: TOTAL LIABILITIES | C42: 2570767 | D42: 2660808
B43: EQUITY
B44: Share capital, paid-in capital and retained earnings | C44: 118957 | D44: 117787
B45: Net income attributable to shareholders | C45: 11688 | D45: 12225
...

Sheet Engine
B1: MAJOR EUROPEAN G-SIB — ALM Engine | Assumptions & Balance Sheet Forecast
B2: SECTION A1 — SCENARIO CONTROL
B4: Scenario ID (linked from Dashboard — do NOT edit here) | C4: =Dashboard!G4 -> 1
B5: ="▶ LIVE SCENARIO: "&CHOOSE($C$4,"Base","Rate Hike","Rate Cut","Stress") -> ▶ LIVE SCENARIO: Base | C5: =CHOOSE($C$4,C7,C8,C9,C10) -> 0 | D5: =CHOOSE($C$4,D7,D8,D9,D10) -> 0.03 | E5: =CHOOSE($C$4,E7,E8,E9,E10) -> 0.025 | F5: =CHOOSE($C$4,F7,F8,F9,F10) -> 0.4 | G5: =CHOOSE($C$4,G7,G8,G9,G10) -> 25 | H5: =CHOOSE($C$4,H7,H8,H9,H10) -> 0.62 | I5: =CHOOSE($C$4,I7,I8,I9,I10) -> 0 | J5: =CHOOSE($C$4,J7,J8,J9,J10) -> 0 | K5: =CHOOSE($C$4,K7,K8,K9,K10) -> 0
C6: Rate Shock | D6: Loan Growth | E6: Dep Growth | F6: Dep Beta | G6: CoR bps | H6: CIR | I6: Trading Gth | J6: IB Loan Gth | K6: Repo Gth
B7: 1 — Base | C7: 0 | D7: 0.03 | E7: 0.025 | F7: 0.4 | G7: 25 | H7: 0.62 | I7: 0 | J7: 0 | K7: 0
B8: 2 — Rate Hike | C8: 0.02 | D8: 0.02 | E8: 0.02 | F8: 0.5 | G8: 30 | H8: 0.63 | I8: 0.02 | J8: 0.01 | K8: 0.01
B9: 3 — Rate Cut | C9: -0.02 | D9: 0.04 | E9: 0.03 | F9: 0.3 | G9: 20 | H9: 0.61 | I9: -0.02 | J9: -0.01 | K9: -0.01
B10: 4 — Stress | C10: 0.03 | D10: 0.01 | E10: 0 | F10: 0.6 | G10: 60 | H10: 0.65 | I10: -0.05 | J10: -0.1 | K10: -0.15
B12: SECTION A2 — MARKET RATE ENVIRONMENT | ECB / Bloomberg
B13: Parameter | C13: 2024A | D13: 2025A | E13: 2026F | F13: 2027F | G13: 2028F | H13: Source
B14: ECB Policy Rate (DFR) | C14: 0.04 | D14: 0.025 | E14: 0.0225 | F14: 0.02 | G14: 0.02 | H14: ECB press conf. 2025A=2.50% reached Sep-25
B15: 3M Euribor | C15: 0.039 | D15: 0.026 | E15: 0.0235 | F15: 0.021 | G15: 0.021 | H15: EMMI fixing avg. DFR+~10bps.
B16: 5Y Swap Rate | C16: 0.029 | D16: 0.028 | E16: 0.027 | F16: 0.026 | G16: 0.0255 | H16: Bloomberg EUR swap
B17: 10Y Swap Rate | C17: 0.027 | D17: 0.026 | E17: 0.0255 | F17: 0.025 | G17: 0.0245 | H17: Bloomberg EUR swap
B18: Δ ECB (formula) | D18: =D14-C14 -> -0.015 | E18: =E14-D14 -> -0.0025 | F18: =F14-E14 -> -0.0025 | G18: =G14-F14 -> 0
B19: Δ Euribor (formula) | D19: =D15-C15 -> -0.013 | E19: =E15-D15 -> -0.0025 | F19: =F15-E15 -> -0.0025 | G19: =G15-F15 -> 0
B21: SECTION A3 — SPREAD ASSUMPTIONS
B22: Spread Parameter | C22: 2024A | D22: 2025A | E22: 2026F | F22: 2027F | G22: 2028F | H22: Source
B23: Loan spread over 3M Euribor | C23: 0.012 | D23: 0.012 | E23: 0.012 | F23: 0.012 | G23: 0.012 | H23: G-SIB loan yield minus Euribor avg
B24: Loan repricing beta | C24: 0.9 | D24: 0.9 | E24: 0.9 | F24: 0.9 | G24: 0.9 | H24: 80% floating rate book
B25: Deposit spread below ECB | C25: -0.02 | D25: -0.02 | E25: -0.02 | F25: -0.02 | G25: -0.02 | H25: ECB minus ~200bps historically
B26: Bond portfolio yield spread | C26: 0.003 | D26: 0.004 | E26: 0.004 | F26: 0.004 | G26: 0.004 | H26: G-SIB FVOCI/AC over 10Y swap
B27: Interbank spread over Euribor | C27: 0.004 | D27: 0.005 | E27: 0.005 | F27: 0.005 | G27: 0.005 | H27: Money market unsecured
B28: Repo spread below ECB DFR | C28: -0.00085 | D28: -0.00085 | E28: -0.00085 | F28: -0.00085 | G28: -0.00085 | H28: ECB DFR minus ESTR ~8.5bps
B29: SU bond issuance spread over 10Y | C29: 0.0065 | D29: 0.0065 | E29: 0.0065 | F29: 0.0065 | G29: 0.0065 | H29: G-SIB SU credit spread ~65bps
B30: Sub debt blended cost (AT1+T2) | C30: 0.025 | D30: 0.025 | E30: 0.025 | F30: 0.025 | G30: 0.025 | H30: Blended AT1+T2 G-SIB Pillar 3
B32: SECTION A4 — BEHAVIOURAL PARAMETERS | EBA/GL/2022/14
B33: Parameter | C33: Value | H33: Regulatory Basis
B34: Retail deposit behavioural duration (yrs) | C34: 2.5 | H34: EBA/GL/2022/14 Table 2: 2-3Y effective duration
B35: Corporate deposit behavioural duration (yrs) | C35: 1 | H35: Basel IRRBB 2016 para 114: 1Y cap
B36: NMD core % (stable) | C36: =CHOOSE($C$4,0.7,0.65,0.72,0.5) -> 0.7 | H36: BCBS IRRBB 2016 para 114: up to 90%, use 70%
B37: ="Model "&Engine!C103&" | Last updated: "&TEXT(Engine!C111,"DD-MMM-YYYY")&" | Prepared by: "&Engine!F111 -> Model v10 | Last updated: 15-May-2026 | Prepared by: Hossam Eltarrass | C37: =1-C36 -> 0.3 | H37: Residual = 100% minus core
B38: Securities: Gov bond % of portfolio | C38: 0.72 | H38: G-SIB 2025 HQLA ~72% sovereign
B39: Securities: Corp bond % of portfolio | C39: 0.28 | H39: Residual. Level 2A HQLA.
B40: Fee income ratio (% total assets) | C40: 0.008 | H40: G-SIB 2025 fees+commissions/total assets
B41: Dividend payout ratio | C41: 0.6 | H41: G-SIB stated policy: 60% payout
B43: SECTION A5 — IRRBB SHOCK PARAMETERS | EBA/GL/2022/14 ANNEX I
B44: Shock Scenario | C44: Shock | D44: Type | H44: Regulatory Source
B45: Parallel Up | C45: 200 | D45: Level | H45: EBA/GL/2022/14 Annex I Scenario 1 — mandatory outlier test
...

Sheet YieldCurve
A1: YieldCurve — Spot Rate Bootstrap & IRRBB Shock Scenarios | 2026F
A2: SECTION 1 — MARKET RATE INPUTS | Engine Sheet 2026F
A3: Parameter | B3: Value (2026F) | C3: Source
A4: ECB Policy Rate (DFR) | B4: =Engine!E14 -> 0.0225 | C4: Engine!E14, 2026F
A5: 3M Euribor | B5: =Engine!E15 -> 0.0235 | C5: Engine!E15, 2026F
A6: 5Y EUR Swap Rate | B6: =Engine!E16 -> 0.027 | C6: Engine!E16, 2026F
A7: 10Y EUR Swap Rate | B7: =Engine!E17 -> 0.0255 | C7: Engine!E17, 2026F
A9: SECTION 2 — PAR RATE INTERPOLATION & SPOT RATE BOOTSTRAPPING (Annual 1Y–10Y)
A10: Year | B10: Par Rate (interp.) | C10: Discount Factor | D10: Spot Rate | E10: Notes
A11: 1 | B11: =Engine!E15+(A11-0.25)/4.75*(Engine!E16-Engine!E15) -> 0.024052632 | C11: =1/(1+B11) -> 0.97651231 | D11: =(1/C11-1)/A11 -> 0.024052632 | E11: 1Y par: interp. 3M Euribor→5Y Swap. DF=1/(1+c). Spot=par rate (single-period)
A12: 2 | B12: =Engine!E15+(A12-0.25)/4.75*(Engine!E16-Engine!E15) -> 0.024789474 | C12: =(1-B12*SUM(C$11:C11))/(1+B12) -> 0.95218852 | D12: =(1/C12-1)/A12 -> 0.025106099 | E12: 2Y par: interp. Bootstrap: DF=(1-c×ΣDF_prev)/(1+c)
A13: 3 | B13: =Engine!E15+(A13-0.25)/4.75*(Engine!E16-Engine!E15) -> 0.025526316 | C13: =(1-B13*SUM(C$11:C12))/(1+B13) -> 0.92710188 | D13: =(1/C13-1)/A13 -> 0.026210036 | E13: 3Y par: interp. Bootstrap sequential
A14: 4 | B14: =Engine!E15+(A14-0.25)/4.75*(Engine!E16-Engine!E15) -> 0.026263158 | C14: =(1-B14*SUM(C$11:C13))/(1+B14) -> 0.90132594 | D14: =(1/C14-1)/A14 -> 0.02736914 | E14: 4Y par: interp. Bootstrap sequential
A15: 5 | B15: =Engine!E15+(A15-0.25)/4.75*(Engine!E16-Engine!E15) -> 0.027 | C15: =(1-B15*SUM(C$11:C14))/(1+B15) -> 0.8749343 | D15: =(1/C15-1)/A15 -> 0.028588592 | E15: 5Y par: =Engine!E16 (market input). Bootstrapped spot
A16: 6 | B16: =Engine!E16+(A16-5)/5*(Engine!E17-Engine!E16) -> 0.0267 | C16: =(1-B16*SUM(C$11:C15))/(1+B16) -> 0.85353455 | D16: =(1/C16-1)/A16 -> 0.02859979 | E16: 6Y par: interp. 5Y→10Y Swap
A17: 7 | B17: =Engine!E16+(A17-5)/5*(Engine!E17-Engine!E16) -> 0.0264 | C17: =(1-B17*SUM(C$11:C16))/(1+B17) -> 0.83318416 | D17: =(1/C17-1)/A17 -> 0.02860212 | E17: 7Y par: interp. 5Y→10Y Swap
A18: 8 | B18: =Engine!E16+(A18-5)/5*(Engine!E17-Engine!E16) -> 0.0261 | C18: =(1-B18*SUM(C$11:C17))/(1+B18) -> 0.81383861 | D18: =(1/C18-1)/A18 -> 0.028593106 | E18: 8Y par: interp. 5Y→10Y Swap
A19: 9 | B19: =Engine!E16+(A19-5)/5*(Engine!E17-Engine!E16) -> 0.0258 | C19: =(1-B19*SUM(C$11:C18))/(1+B19) -> 0.79545564 | D19: =(1/C19-1)/A19 -> 0.028571236 | E19: 9Y par: interp. 5Y→10Y Swap
A20: 10 | B20: =Engine!E16+(A20-5)/5*(Engine!E17-Engine!E16) -> 0.0255 | C20: =(1-B20*SUM(C$11:C19))/(1+B20) -> 0.77799519 | D20: =(1/C20-1)/A20 -> 0.0285355 | E20: 10Y par: =Engine!E17 (market input). Bootstrapped spot
A22: SECTION 3 — YIELD CURVE SUMMARY | Base Case + IRRBB EBA/GL/2022/14 Shock Scenarios
C23: BASE CASE | F23: PAR. UP +200bps | H23: PAR. DOWN −200bps | J23: STEEPENER (+90/−90) | L23: FLATTENER (−90/+90)
A24: Tenor | B24: T (yrs) | C24: Spot Rate | D24: Disc. Factor | E24: Fwd Rate→next | F24: Spot Rate | G24: Disc. Factor | H24: Spot Rate | I24: Disc. Factor | J24: Spot Rate | K24: Disc. Factor | L24: Spot Rate | M24: Disc. Factor
A25: Overnight | B25: =1/365 -> 0.002739726 | C25: =Engine!E14 -> 0.0225 | D25: =1/(1+C25*B25) -> 0.99993836 | E25: =(D25/D26-1)/(B26-B25) -> 0.023509631 | F25: =C25+Engine!$C$45/10000 -> 0.0425 | G25: =1/(1+F25*B25) -> 0.99988358 | H25: =C25+Engine!$C$46/10000 -> 0.0025 | I25: =1/(1+H25*B25) -> 0.99999315 | J25: =C25+Engine!$C$47/10000*(1-2*B25/10) -> 0.031495068 | K25: =1/(1+J25*B25) -> 0.99991372 | L25: =C25+Engine!$C$48/10000*(1-2*B25/10) -> 0.013504932 | M25: =1/(1+L25*B25) -> 0.999963
A26: 3 Month | B26: =1/4 -> 0.25 | C26: =Engine!E15 -> 0.0235 | D26: =1/(1+C26*B26) -> 0.99415931 | E26: =(D26/D27-1)/(B27-B26) -> 0.023729013 | F26: =C26+Engine!$C$45/10000 -> 0.0435 | G26: =1/(1+F26*B26) -> 0.98924199 | H26: =C26+Engine!$C$46/10000 -> 0.0035 | I26: =1/(1+H26*B26) -> 0.99912576 | J26: =C26+Engine!$C$47/10000*(1-2*B26/10) -> 0.03205 | K26: =1/(1+J26*B26) -> 0.99205119 | L26: =C26+Engine!$C$48/10000*(1-2*B26/10) -> 0.01495 | M26: =1/(1+L26*B26) -> 0.99627642
A27: 6 Month | B27: =1/2 -> 0.5 | C27: =C26+(B27-B26)/(B28-B26)*(C28-C26) -> 0.023684211 | D27: =1/(1+C27*B27) -> 0.98829649 | E27: =(D27/D28-1)/(B28-B27) -> 0.024135241 | F27: =C27+Engine!$C$45/10000 -> 0.043684211 | G27: =1/(1+F27*B27) -> 0.97862477 | H27: =C27+Engine!$C$46/10000 -> 0.0036842105 | I27: =1/(1+H27*B27) -> 0.99816128 | J27: =C27+Engine!$C$47/10000*(1-2*B27/10) -> 0.031784211 | K27: =1/(1+J27*B27) -> 0.9843565 | L27: =C27+Engine!$C$48/10000*(1-2*B27/10) -> 0.015584211 | M27: =1/(1+L27*B27) -> 0.99226814
A28: 1 Year | B28: =1 -> 1 | C28: =D11 -> 0.024052632 | D28: =1/(1+C28*B28) -> 0.97651231 | E28: =(D28/D29-1)/(B29-B28) -> 0.025545139 | F28: =C28+Engine!$C$45/10000 -> 0.044052632 | G28: =1/(1+F28*B28) -> 0.95780612 | H28: =C28+Engine!$C$46/10000 -> 0.0040526316 | I28: =1/(1+H28*B28) -> 0.99596373 | J28: =C28+Engine!$C$47/10000*(1-2*B28/10) -> 0.031252632 | K28: =1/(1+J28*B28) -> 0.9696945 | L28: =C28+Engine!$C$48/10000*(1-2*B28/10) -> 0.016852632 | M28: =1/(1+L28*B28) -> 0.98342667
A29: 2 Year | B29: =2 -> 2 | C29: =D12 -> 0.025106099 | D29: =1/(1+C29*B29) -> 0.95218852 | E29: =(D29/D30-1)/(B30-B29) -> 0.029432389 | F29: =C29+Engine!$C$45/10000 -> 0.045106099 | G29: =1/(1+F29*B29) -> 0.91725262 | H29: =C29+Engine!$C$46/10000 -> 0.005106099 | I29: =1/(1+H29*B29) -> 0.98989104 | J29: =C29+Engine!$C$47/10000*(1-2*B29/10) -> 0.030506099 | K29: =1/(1+J29*B29) -> 0.94249623 | L29: =C29+Engine!$C$48/10000*(1-2*B29/10) -> 0.019706099 | M29: =1/(1+L29*B29) -> 0.96208222
A30: 5 Year | B30: =5 -> 5 | C30: =D15 -> 0.028588592 | D30: =1/(1+C30*B30) -> 0.8749343 | E30: =(D30/D31-1)/(B31-B30) -> 0.024920235 | F30: =C30+Engine!$C$45/10000 -> 0.048588592 | G30: =1/(1+F30*B30) -> 0.80454215 | H30: =C30+Engine!$C$46/10000 -> 0.0085885922 | I30: =1/(1+H30*B30) -> 0.95882521 | J30: =C30+Engine!$C$47/10000*(1-2*B30/10) -> 0.028588592 | K30: =1/(1+J30*B30) -> 0.8749343 | L30: =C30+Engine!$C$48/10000*(1-2*B30/10) -> 0.028588592 | M30: =1/(1+L30*B30) -> 0.8749343
A31: 10 Year | B31: =10 -> 10 | C31: =D20 -> 0.0285355 | D31: =1/(1+C31*B31) -> 0.77799519 | E31: =(D31/D32-1)/(B32-B31) -> 0.022975852 | F31: =C31+Engine!$C$45/10000 -> 0.0485355 | G31: =1/(1+F31*B31) -> 0.67323973 | H31: =C31+Engine!$C$46/10000 -> 0.0085354995 | I31: =1/(1+H31*B31) -> 0.92135753 | J31: =C31+Engine!$C$47/10000*(1-2*B31/10) -> 0.0195355 | K31: =1/(1+J31*B31) -> 0.83657157 | L31: =C31+Engine!$C$48/10000*(1-2*B31/10) -> 0.0375355 | M31: =1/(1+L31*B31) -> 0.72708501
A32: 3 Year | B32: =3 -> 3 | C32: =D13 -> 0.026210036 | D32: =1/(1+C32*B32) -> 0.92710188 | E32: =(D32/D33-1)/(B33-B32) -> 0.028597802 | F32: =C32+Engine!$C$45/10000 -> 0.046210036 | G32: =1/(1+F32*B32) -> 0.87824834 | H32: =C32+Engine!$C$46/10000 -> 0.0062100363 | I32: =1/(1+H32*B32) -> 0.98171062 | J32: =C32+Engine!$C$47/10000*(1-2*B32/10) -> 0.029810036 | K32: =1/(1+J32*B32) -> 0.91791111 | L32: =C32+Engine!$C$48/10000*(1-2*B32/10) -> 0.022610036 | M32: =1/(1+L32*B32) -> 0.93647856
A33: 4 Year | B33: =4 -> 4 | C33: =D14 -> 0.02736914 | D33: =1/(1+C33*B33) -> 0.90132594 | E33: =(D33/D34-1)/(B34-B33) -> 0.027996166 | F33: =C33+Engine!$C$45/10000 -> 0.04736914 | G33: =1/(1+F33*B33) -> 0.84070593 | H33: =C33+Engine!$C$46/10000 -> 0.00736914 | I33: =1/(1+H33*B33) -> 0.97136743 | J33: =C33+Engine!$C$47/10000*(1-2*B33/10) -> 0.02916914 | K33: =1/(1+J33*B33) -> 0.89551445 | L33: =C33+Engine!$C$48/10000*(1-2*B33/10) -> 0.02556914 | M33: =1/(1+L33*B33) -> 0.90721334
A34: 6 Year | B34: =6 -> 6 | C34: =D16 -> 0.02859979 | D34: =1/(1+C34*B34) -> 0.85353455 | E34: =(D34/D35-1)/(B35-B34) -> 0.024424831 | F34: =C34+Engine!$C$45/10000 -> 0.04859979 | G34: =1/(1+F34*B34) -> 0.77423426 | H34: =C34+Engine!$C$46/10000 -> 0.0085997901 | I34: =1/(1+H34*B34) -> 0.95093305 | J34: =C34+Engine!$C$47/10000*(1-2*B34/10) -> 0.02679979 | K34: =1/(1+J34*B34) -> 0.86147578 | L34: =C34+Engine!$C$48/10000*(1-2*B34/10) -> 0.03039979 | M34: =1/(1+L34*B34) -> 0.84573838
A35: 7 Year | B35: =7 -> 7 | C35: =D17 -> 0.02860212 | D35: =1/(1+C35*B35) -> 0.83318416 | E35: =(D35/D36-1)/(B36-B35) -> 0.023770749 | F35: =C35+Engine!$C$45/10000 -> 0.04860212 | G35: =1/(1+F35*B35) -> 0.74614903 | H35: =C35+Engine!$C$46/10000 -> 0.0086021203 | I35: =1/(1+H35*B35) -> 0.94320506 | J35: =C35+Engine!$C$47/10000*(1-2*B35/10) -> 0.02500212 | K35: =1/(1+J35*B35) -> 0.85105308 | L35: =C35+Engine!$C$48/10000*(1-2*B35/10) -> 0.03220212 | M35: =1/(1+L35*B35) -> 0.81605018
A36: 8 Year | B36: =8 -> 8 | C36: =D18 -> 0.028593106 | D36: =1/(1+C36*B36) -> 0.81383861 | E36: =(D36/D37-1)/(B37-B36) -> #VALUE! | F36: =C36+Engine!$C$45/10000 -> 0.048593106 | G36: =1/(1+F36*B36) -> 0.72007468 | H36: =C36+Engine!$C$46/10000 -> 0.0085931059 | I36: =1/(1+H36*B36) -> 0.93567703 | J36: =C36+Engine!$C$47/10000*(1-2*B36/10) -> 0.023193106 | K36: =1/(1+J36*B36) -> 0.84349403 | L36: =C36+Engine!$C$48/10000*(1-2*B36/10) -> 0.033993106 | M36: =1/(1+L36*B36) -> 0.78619761
A37: 9 Year | B37: ="Model "&Engine!C103&" | Last updated: "&TEXT(Engine!C111,"DD-MMM-YYYY")&" | Prepared by: "&Engine!F111 -> Model v10 | Last updated: 15-May-2026 | Prepared by: Hossam Eltarrass | C37: =D19 -> 0.028571236 | D37: =1/(1+C37*B37) -> #VALUE! | F37: =C37+Engine!$C$45/10000 -> 0.048571236 | G37: =1/(1+F37*B37) -> #VALUE! | H37: =C37+Engine!$C$46/10000 -> 0.0085712361 | I37: =1/(1+H37*B37) -> #VALUE! | J37: =C37+Engine!$C$47/10000*(1-2*B37/10) -> #VALUE! | K37: =1/(1+J37*B37) -> #VALUE! | L37: =C37+Engine!$C$48/10000*(1-2*B37/10) -> #VALUE! | M37: =1/(1+L37*B37) -> #VALUE!

Sheet Model
B1: MAJOR EUROPEAN G-SIB — ALM Model | Calculations | All figures EUR millions
B2: ="SECTION 1 — NII SIMULATION 2025A | Scenario: "&CHOOSE(Engine!C4,"Base","Rate Hike","Rate Cut","Stress") -> SECTION 1 — NII SIMULATION 2025A | Scenario: Base
B3: B — Asset / Liability | C3: Balance (€m) | D3: Rate | E3: Interest (€m)
B4: Cash & CB reserves (earns ECB DFR rate — NOT loan rate) | C4: =Engine!D126 -> 211330 | D4: =Engine!D14 -> 0.025 | E4: =C4*D4 -> 5283.25
B5: Loans to customers | C5: =Engine!D128 -> 897358 | D5: =Engine!D116 -> 0.038 | E5: =C5*D5 -> 34099.604
B6: Interbank loans | C6: =Engine!D129 -> 26259 | D6: =Engine!D121 -> 0.031 | E6: =C6*D6 -> 814.029
B7: Securities portfolio | C7: =Engine!D130 -> 153107 | D7: =Engine!D119 -> 0.03 | E7: =C7*D7 -> 4593.21
B8: Total Interest Income | C8: =SUM(C4:C7) -> 1288054 | E8: =SUM(E4:E7) -> 44790.093
B10: B — Liability | C10: Balance (€m) | D10: Rate | E10: Interest Cost (€m)
B11: Customer deposits | C11: =Engine!D136 -> 1075564 | D11: =Engine!D117 -> 0.005 | E11: =C11*D11 -> 5377.82
B12: Interbank funding | C12: =Engine!D137 -> 69938 | D12: =Engine!D121 -> 0.031 | E12: =C12*D12 -> 2168.078
B13: Repo funding | C13: =Engine!D138 -> 357947 | D13: =Engine!D118 -> 0.02415 | E13: =C13*D13 -> 8644.4201
B14: Bonds issued | C14: =Engine!D139 -> 173933 | D14: =Engine!D120 -> 0.0325 | E14: =C14*D14 -> 5652.8225
B15: Subordinated debt | C15: =Engine!D140 -> 34468 | D15: =Engine!D122 -> 0.025 | E15: =C15*D15 -> 861.7
B16: Total Interest Expense | C16: =SUM(C11:C15) -> 1711850 | E16: =SUM(E11:E15) -> 22704.841
B18: ★ NET INTEREST INCOME | C18: =E8-E16 -> 22085.252
B19: Average earning assets (see guide for formula) | C19: =(Engine!C126+Engine!C128+Engine!C129+Engine!C130+Engine!D126+Engine!D128+Engine!D129+Engine!D130)/2 -> 1275211.5
B20: NIM | C20: =C18/C19 -> 0.017318894
B21: ="SECTION 2 — P&L MODEL | 2025A→2028F | Scenario: "&CHOOSE(Engine!C4,"Base","Rate Hike","Rate Cut","Stress") -> SECTION 2 — P&L MODEL | 2025A→2028F | Scenario: Base
B22: B — P&L Line | C22: 2025A | D22: 2026F | E22: 2027F | F22: 2028F
B23: Net Interest Income | C23: =C18 -> 22085.252 | D23: =(Engine!E126*Engine!E14)+(Engine!E128*Engine!E116)+(Engine!E129*Engine!E121)+(Engine!E130*Engine!E119)-((Engine!E136*Engine!E117)+(Engine!E137*Engine!E121)+(Engine!E138*Engine!E118)+(Engine!E139*Engine!E120)+(Engine!E140*Engine!E122)) -> 22685.669 | E23: =(Engine!F126*Engine!F14)+(Engine!F128*Engine!F116)+(Engine!F129*Engine!F121)+(Engine!F130*Engine!F119)-((Engine!F136*Engine!F117)+(Engine!F137*Engine!F121)+(Engine!F138*Engine!F118)+(Engine!F139*Engine!F120)+(Engine!F140*Engine!F122)) -> 23224.923 | F23: =(Engine!G126*Engine!G14)+(Engine!G128*Engine!G116)+(Engine!G129*Engine!G121)+(Engine!G130*Engine!G119)-((Engine!G136*Engine!G117)+(Engine!G137*Engine!G121)+(Engine!G138*Engine!G118)+(Engine!G139*Engine!G120)+(Engine!G140*Engine!G122)) -> 24295.945
B24: Fee income | C24: =Engine!D132*Engine!$C$40 -> 22343.848 | D24: =Engine!E132*Engine!$C$40 -> 22670.697 | E24: =Engine!F132*Engine!$C$40 -> 23004.312 | F24: =Engine!G132*Engine!$C$40 -> 23345.323
B25: Total Revenue | C25: =C23+C24 -> 44429.1 | D25: =D23+D24 -> 45356.365 | E25: =E23+E24 -> 46229.236 | F25: =F23+F24 -> 47641.269
B26: Operating Expenses | C26: =C25*(-Engine!$H$5) -> -27546.042 | D26: =D25*(-Engine!$H$5) -> -28120.946 | E26: =E25*(-Engine!$H$5) -> -28662.126 | F26: =F25*(-Engine!$H$5) -> -29537.586
B27: Gross Operating Income | C27: =C25+C26 -> 16883.058 | D27: =D25+D26 -> 17235.419 | E27: =E25+E26 -> 17567.11 | F27: =F25+F26 -> 18103.682
B28: Provisions / CoR | C28: =-(Engine!D128*Engine!$G$5/10000) -> -2243.395 | D28: =-(Engine!E128*Engine!$G$5/10000) -> -2310.6968 | E28: =-(Engine!F128*Engine!$G$5/10000) -> -2380.0178 | F28: =-(Engine!G128*Engine!$G$5/10000) -> -2451.4183
B29: Pre-Tax Income | C29: =C27+C28 -> 14639.663 | D29: =D27+D28 -> 14924.722 | E29: =E27+E28 -> 15187.092 | F29: =F27+F28 -> 15652.264
B30: Income Tax (25%) | C30: =C29*(-Engine!$C$156) -> -3659.9158 | D30: =D29*(-Engine!$C$156) -> -3731.1805 | E30: =E29*(-Engine!$C$156) -> -3796.7729 | F30: =F29*(-Engine!$C$156) -> -3913.0659
B31: Net Income | C31: =C29+C30 -> 10979.747 | D31: =D29+D30 -> 11193.541 | E31: =E29+E30 -> 11390.319 | F31: =F29+F30 -> 11739.198
B32: Dividend (60% payout) | C32: =C31*(-Engine!$C$41) -> -6587.8484 | D32: =D31*(-Engine!$C$41) -> -6716.1249 | E32: =E31*(-Engine!$C$41) -> -6834.1913 | F32: =F31*(-Engine!$C$41) -> -7043.5187
B33: Retained Earnings | C33: =C31+C32 -> 4391.899 | D33: =D31*0.4 -> 4477.4166 | E33: =E31+E32 -> 4556.1275 | F33: =F31+F32 -> 4695.6791
B34: ROE | C34: =C31/Engine!D145 -> 0.083071031 | D34: =D31/((Engine!D145+Engine!E145)/2) -> 0.083278024 | E34: =E31/((Engine!E145+Engine!G145)/2) -> 0.080624402 | F34: =F31/((Engine!F145+Engine!G145)/2) -> 0.081775265
B35: ROA | C35: =C31/Engine!D132 -> 0.003931193 | D35: =D31/Engine!E132 -> 0.0039499594 | E35: =E31/Engine!F132 -> 0.0039611074 | F35: =F31/Engine!G132 -> 0.0040228007
B36: CIR check | C36: =(-C26)/C25 -> 0.62 | D36: =(-D26)/D25 -> 0.62 | E36: =(-E26)/E25 -> 0.62 | F36: =(-F26)/F25 -> 0.62
B37: ="Model "&Engine!C103&" | Last updated: "&TEXT(Engine!C111,"DD-MMM-YYYY")&" | Prepared by: "&Engine!F111 -> Model v10 | Last updated: 15-May-2026 | Prepared by: Hossam Eltarrass
B38: ="SECTION 3 — REPRICING GAP 2025A | EBA/GL/2022/14 | Scenario: "&CHOOSE(Engine!C4,"Base","Rate Hike","Rate Cut","Stress") -> SECTION 3 — REPRICING GAP 2025A | EBA/GL/2022/14 | Scenario: Base
B39: B — Time Bucket | C39: Assets (€m) | D39: Liabilities (€m) | E39: GAP | F39: Cum. GAP | G39: ΔNii per 100bps
B40: Overnight | C40: =Engine!D126+Engine!D129*0.5 -> 224459.5 | D40: =Engine!D136*Engine!C37+Engine!D137*0.6+Engine!D138 -> 722579 | E40: =C40-D40 -> -498119.5 | F40: =E40 -> -498119.5 | G40: =E40*Engine!$C$176*(1/365) -> -4.0941329
B41: 0–3 Months | C41: =Engine!D128*Engine!$C$160+Engine!D129*0.5+Engine!D130*0.05 -> 828407.05 | D41: =Engine!D136*Engine!$C$36*Engine!$C$168+Engine!D137*0.4 -> 103264.68 | E41: =C41-D41 -> 725142.37 | F41: =F40+E41 -> 227022.87 | G41: =E41*0.01*Engine!$C$177 -> 906.42796
B42: 3–6 Months | C42: =Engine!D128*Engine!$C$161+Engine!D130*0.05 -> 25602.51 | D42: =Engine!D136*Engine!$C$36*Engine!$C$169 -> 75289.48 | E42: =C42-D42 -> -49686.97 | F42: =F41+E42 -> 177335.9 | G42: =E42*0.01*Engine!$C$178 -> -186.32614
...
